<?xml version="1.0"?>
<robot xmlns:xacro="http://www.ros.org/wiki/xacro">
    
    <xacro:include filename="inertial_macros.xacro"/>

    <material name="white">
        <color rgba="1 1 1 1"/>
    </material>

    <material name="orange">
        <color rgba="1 0.3 0.1 1"/>
    </material>

    <material name="blue">
        <color rgba="0.2 0.2 1 1"/>
    </material>

    <material name="black">
        <color rgba="0 0 0 1"/>
    </material>

    <material name="red">
        <color rgba="1 0 0 1"/>
    </material>
    
    <gazebo>
        <plugin filename="libgazebo_ros_control.so" name="gazebo_ros_control">
          <robotSimType>sr_gazebo_sim/SrGazeboHWSim</robotSimType>
        </plugin>
      </gazebo>

    <!-- BASE LINK/-->

    <link name="base_link">

    </link>


    <!--CHASSIS LINK/-->

    <joint name="chassis_joint" type="fixed">
        <parent link="base_link"/>
        <child link="chassis"/>
        <origin xyz="0.0 0.0 0.0"/>
    </joint>

    <link name="chassis">
        <visual> 
            <origin xyz="0.0 0.0 0.075"/>
            <geometry>
                <box size="0.3 0.3 0.15"/>
            </geometry>
            <material name="blue"/>
        </visual>
        <collision> 
            <origin xyz="0.0 0.0 0.075"/>
            <geometry>
                <box size="0.3 0.3 0.15"/>
            </geometry>
        </collision>
        <xacro:inertial_box mass="1.5" x="0.3" y="0.3" z="0.15">
            <origin xyz="0.0 0.0 0.075" rpy="0.0 0.0 0.0"/>
        </xacro:inertial_box>
    </link>

    <gazebo reference = "chassis">
        <material>Gazebo/Blue</material>
    </gazebo>


    <!-- LEFT WHEEL LINK -->

    <joint name="left_wheel_joint" type="continuous">
            <parent link="base_link"/>
            <child link="left_wheel"/>
            <origin xyz="-0.1 -0.175 0.0" rpy="-${pi/2}  0.0 0.0"/>
            <axis xyz="0.0 0.0 -1.0"/>
    </joint>

    <link name="left_wheel">
        <visual>
            <origin xyz="0.0 0.0 0.0" rpy="0.0  0.0 0.0"/>
            <geometry>
                <cylinder radius="0.05" length="0.04"/>

            </geometry>
            <material name="white"/>
        </visual>
        <collision>
            <geometry>
                <cylinder radius="0.05" length="0.04"/>
            </geometry>
        </collision>
        <xacro:inertial_cylinder mass="0.15"  radius="0.05" length="0.04">
            <origin xyz="0.0 0.0 0.0" rpy="0.0 0.0 0.0"/>
        </xacro:inertial_cylinder >
    </link>

    <gazebo reference = "left_wheel">
        <material>Gazebo/White</material>
    </gazebo>


    <!-- RIGHT WHEEL LINK -->

    <joint name="right_wheel_joint" type="continuous">
            <parent link="base_link"/>
            <child link="right_wheel"/>
            <origin xyz="-0.1 0.175 0.0" rpy="${pi/2}  0.0 0.0"/>
            <axis xyz="0.0 0.0 1.0"/>
    </joint>

    <link name="right_wheel">
        <visual>
            <origin xyz="0.0 0.0 0.0" rpy="0.0 0.0 0.0"/>
            <geometry>
                <cylinder radius="0.05" length="0.04"/>
            </geometry>
            <material name="white"/>
        </visual>
        <collision>
            <geometry>
                <cylinder radius="0.05" length="0.04"/>
            </geometry>
        </collision>
        <xacro:inertial_cylinder mass="0.15" length="0.04" radius="0.05" >
            <origin xyz="0.0 0.0 0.0" rpy="0.0 0.0 0.0"/>
        </xacro:inertial_cylinder >
    </link>
    
    <gazebo reference = "right_wheel">
        <material>Gazebo/White</material>
    </gazebo>


    <!-- CASTER WHEEL LINK-->

    <joint name="left_wheel_2_joint" type="continuous">
        <parent link="base_link"/>
        <child link="left_wheel_2"/>
        <origin xyz="0.1 -0.175 0.0" rpy="-${pi/2}  0.0 0.0"/>
        <axis xyz="0.0 0.0 -1.0"/>
    </joint>

    <link name="left_wheel_2">
        <visual>
            <origin xyz="0.0 0.0 0.0" rpy="0.0  0.0 0.0"/>
            <geometry>
                <cylinder radius="0.05" length="0.04"/>
            </geometry>
            <material name="white"/>
        </visual>
        <collision>
            <geometry>
                <cylinder radius="0.05" length="0.04"/>
            </geometry>
        </collision>
        <xacro:inertial_cylinder mass="0.15"  radius="0.05" length="0.04">
            <origin xyz="0.0 0.0 0.0" rpy="0.0 0.0 0.0"/>
        </xacro:inertial_cylinder >
    </link>
    <gazebo reference = "left_wheel_2">
        <material>Gazebo/White</material>
    </gazebo>


<!-- RIGHT WHEEL LINK -->

    <joint name="right_wheel_2_joint" type="continuous">
            <parent link="base_link"/>
            <child link="right_wheel_2"/>
            <origin xyz="0.1 0.175 0.0" rpy="${pi/2}  0.0 0.0"/>
            <axis xyz="0.0 0.0 1.0"/>
    </joint>

    <link name="right_wheel_2">
        <visual>
            <origin xyz="0.0 0.0 0.0" rpy="0.0 0.0 0.0"/>
            <geometry>
                <cylinder radius="0.05" length="0.04"/>
            </geometry>
            <material name="white"/>
        </visual>
        <collision>
            <geometry>
                <cylinder radius="0.05" length="0.04"/>
            </geometry>
        </collision>
        <xacro:inertial_cylinder mass="0.15" length="0.04" radius="0.05" >
            <origin xyz="0.0 0.0 0.0" rpy="0.0 0.0 0.0"/>
        </xacro:inertial_cylinder >
    </link>
    <gazebo reference = "right_wheel_2">
        <material>Gazebo/White</material>
    </gazebo>

    <link name="pole">
        <visual>
            <geometry>
                <cylinder length="0.3" radius="0.01"/>
            </geometry>
            <material name="orange"/>
            <origin rpy="0.0 0.0 -0.15" xyz="0.0 0.0 0.3"/>
        </visual>
        <collision>
            <geometry>
                <cylinder length="0.3" radius="0.01"/>
            </geometry>
        </collision>
        <xacro:inertial_cylinder mass="0.0"  radius="0.01" length="0.03">
            <origin xyz="0.0 0.0 0.0" rpy="0.0 0.0 0.0"/>
        </xacro:inertial_cylinder >
    </link>
    
    <joint name="pole_joint" type="revolute">
        <parent link="chassis"/>
        <child link="pole"/>
        <origin xyz="0.0 0.0 0.0" rpy="0.0 0.0 0.0"/>
        <axis xyz="0.0 1.0 0.0"/>
        <limit effort="1000.0" lower="-0.78" upper="0.78" velocity="1.0"/>
    </joint>
    
    <link name="conector_pole">
        <visual>
            <geometry>
                <box size="0.02 0.02 0.02"/>
            </geometry>
            <material name="black"/>
            <origin rpy="0.0 0.0 0.0" xyz="0.0 0.0 0.0"/>
        </visual>
        <collision>
            <geometry>
                <box size="0.02 0.02 0.02"/>
            </geometry>
        </collision>
        <xacro:inertial_box mass="0.0" x="0.02" y="0.02" z="0.02">
            <origin xyz="0.0 0.0 0.0" rpy="0.0 0.0 0.0"/>
        </xacro:inertial_box>
    </link>

    <joint name="conector_pole_joint" type="fixed">
        <parent link="pole"/>
        <child link="conector_pole"/>
        <origin xyz="0.0 0.0 0.45" />
    </joint>

    <gazebo reference = "pole">
        <material>Gazebo/Orange</material>
    </gazebo>

    <gazebo reference = "conector_pole">
        <material>Gazebo/Black</material>
    </gazebo>
</robot>