<?xml version="1.0"?>
<robot xmlns:xacro="http://www.ros.org/wiki/xacro">

    
    <xacro:include filename="inertial_macros.xacro"/>


    
    <joint name="element_link_joint" type="fixed">
        <axis xyz="1 0 0"/>
        <parent link="chassis"/>
        <child link="element_link"/>
        <origin xyz="-0.075 0 0.06" rpy="0 0 0"/>
    </joint>

    <link name="element_link">  
        <visual>
            <origin xyz="0 0 0" rpy="0 0 0"/>
            <geometry>
                <box size="0.15 0.02 0.02"/>
            </geometry>
            <material name="red"/>
        </visual>
        <collision>
            <origin xyz="0 0 0" rpy="0 0 0"/>
            <geometry>
                <box size="0.15 0.02 0.02"/>
            </geometry>
        </collision>
        <xacro:inertial_box mass="0.0001" x="0.3" y="0.02" z="0.02">
            <origin xyz="0 0 0" rpy="0 0 0"/>
        </xacro:inertial_box>
    </link>

    <gazebo reference="element_link">
        <material>Gazebo/Red</material>
    </gazebo>

        <joint name="conector_joint" type="revolute">
                <parent link="element_link"/>
                <child link="conector_link"/>
                <axis xyz="0 0 1"/>
                <limit effort="1000.0" lower="-1.5708" upper="1.5708" velocity="0.5"/>
                <origin xyz="-0.075 0 0" rpy="0 0 0"/>
        </joint>

        <link name="conector_link">
            <visual>
                <origin xyz="0 0 0" rpy="0 0 0"/>
                <geometry>
                    <box size="0.03 0.03 0.03"/>
                </geometry>
                <material name="black"/>
            </visual>
            <collision>
                <origin xyz="0 0 0" rpy="0 0 0"/>
                <geometry>
                    <box size="0.03 0.03 0.03"/>
                </geometry>
            </collision>
            <xacro:inertial_box mass="0.0001" x="0.01" y="0.03" z="0.03">
                <origin xyz="0 0 0" rpy="0 0 0"/>
            </xacro:inertial_box>
        </link>
        
        <gazebo reference="conector_link">
            <material>Gazebo/Black</material>
        </gazebo>

    <!--element2/-->
        <joint name="element2_link_joint" type="fixed">
            <parent link="conector_link"/>
            <child link="element2_link"/>
            <origin xyz="0 0 0" rpy="0 0 0"/>
        </joint>

        <link name="element2_link">
            <visual>
                <origin xyz="-0.075 0 0" rpy="0 0 0"/>
                <geometry>
                    <box size="0.15 0.02 0.02"/>
                </geometry>
                <material name="red"/>
            </visual>
            <collision>
                <origin xyz="-0.075 0 0" rpy="0 0 0"/>
                <geometry>
                    <box size="0.15 0.02 0.02"/>
                </geometry>
            </collision>
            <xacro:inertial_box mass="0.0001" x="0.15" y="0.02" z="0.02">
                <origin xyz="-0.075 0 0" rpy="0 0 0"/>
            </xacro:inertial_box>
        </link>

        <gazebo reference="element2_link">
            <material>Gazebo/Red</material>
        </gazebo>


        <!--joint name="chassis_2_joint" type="fixed">
            <parent link="element2_link"/>
            <child link="chassis_2"/>
            <origin xyz="0 0 0" rpy="0 0 0"/>
        </joint>

    
        <link name="chassis_2">
            <visual> 
                <origin xyz="-0.2 0 0.02" rpy="0 0 0"/>
                <geometry>
                    <box size="0.3 0.3 0.15"/>
                </geometry>
                <material name="blue"/>
            </visual>
            <collision> 
                <origin xyz="-0.2 0 0.02" rpy="0 0 0"/>
                <geometry>
                    <box size="0.3 0.3 0.15"/>
                </geometry>
            </collision>
            <xacro:inertial_box mass="0.3" x="0.3" y="0.3" z="0.15">
                <origin xyz="-0.2 0 0.02" rpy="0 0 0"/>
            </xacro:inertial_box>
        </link>
    
        <gazebo reference = "chassis_2">
            <material>Gazebo/Blue</material>
        </gazebo>
    
    
    
        <joint name="left_wheel_2_joint" type="continuous">
                <parent link="chassis_2"/>
                <child link="left_wheel_2"/>
                <origin xyz="-0.1 0.175 -0.075" rpy="-${pi/2} 0 0"/>
                <axis xyz="0 0 1"/>
        </joint>
    
        <link name="left_wheel_2">
            <visual>
                <origin xyz="0 0 0" rpy="0 0 0"/>
                <geometry>
                    <cylinder radius="0.05" length="0.04"/>
                </geometry>
                <material name="white"/>
            </visual>
            <collision>
                <origin xyz="0 0 0" rpy="0 0 0"/>
                <geometry>
                    <cylinder radius="0.05" length="0.04"/>
                </geometry>
            </collision>
            <xacro:inertial_cylinder mass="0.1"  radius="0.05" length="0.04">
                <origin xyz="0 0 0" rpy="0 0 0"/>
            </xacro:inertial_cylinder >
        </link>
    
        <gazebo reference = "left_wheel_2">
            <material>Gazebo/White</material>
        </gazebo>
    
        <joint name="right_wheel_2_joint" type="continuous">
                <parent link="chassis_2"/>
                <child link="right_wheel_2"/>
                <origin xyz="-0.1 -0.175 -0.075" rpy="${pi/2} 0 0"/>
                <axis xyz="0 0 -1"/>
        </joint>
    
        <link name="right_wheel_2">
            <visual>
                <origin xyz="0 0 0" rpy="0 0 0"/>
                <geometry>
                    <cylinder radius="0.05" length="0.04"/>
                </geometry>
                <material name="white"/>
            </visual>
            <collision>
                <origin xyz="0 0 0" rpy="0 0 0"/>
                <geometry>
                    <cylinder radius="0.05" length="0.04"/>
                </geometry>
            </collision>
            <xacro:inertial_cylinder mass="0.1"  radius="0.05" length="0.04">
                <origin xyz="0 0 0" rpy="0 0 0"/>
            </xacro:inertial_cylinder >
        </link>
        
        <gazebo reference = "right_wheel_2">
            <material>Gazebo/White</material>
        </gazebo>
    
        <!joint name="caster_wheel_2_joint" type="fixed">
            <parent link="chassis_2"/>
            <child link="caster_wheel_2"/>
            <origin xyz="0.1 0 -0.075" rpy="0 0 0"/>
        </joint>
    
        <link name="caster_wheel_2">
            <visual>
                <origin xyz="0 0 0" rpy="0 0 0"/>
                <geometry>
                    <sphere radius="0.05"/>
                </geometry>
                <material name="white"/>
            </visual>
            <collision>
                <origin xyz="0 0 0" rpy="0 0 0"/>
                <geometry>
                    <sphere radius="0.05"/>
                </geometry>
            </collision>
            <xacro:inertial_sphere mass="0.1" radius="0.05" >
                <origin xyz="0 0 0" rpy="0 0 0"/>
            </xacro:inertial_sphere>   
        </link>
    
        <gazebo reference = "caster_wheel_2">
            <material>Gazebo/White</material>
            <mu1 value = "0.001"/>
            <mu2 value = "0.001"/>
        </gazebo-->  
        

</robot>
